<?xml version="1.0" ?>
<robot name="ur5e_robot">
      <!-- <material name="LightGrey">
        <color rgba="0.7 0.7 0.7 1.0"/>
      </material> -->
  <link name="base_link"/>
  <link name="base_offset_link"/>
  <link name="base_link_inertia">
    <visual>
      <origin rpy="0 0 3.141592653589793" xyz="0 0 0"/>
      <geometry>
        <mesh filename="meshes/visual/base.dae"/>
      </geometry>
      <!-- <material name="LightGrey"/> -->
    </visual>
    <collision>
      <origin rpy="0 0 3.141592653589793" xyz="0 0 0"/>
      <geometry>
        <mesh filename="meshes/collision/base.stl"/>
      </geometry>
    </collision>
    <inertial>
      <mass value="4.0"/>
      <origin rpy="0 0 0" xyz="0 0 0"/>
      <inertia ixx="0.00443333156" ixy="0.0" ixz="0.0" iyy="0.00443333156" iyz="0.0" izz="0.0072"/>
    </inertial>
  </link>
  <link name="shoulder_link">
    <visual>
      <origin rpy="0 0 3.141592653589793" xyz="0 0 0"/>
      <geometry>
        <mesh filename="meshes/visual/shoulder.dae"/>
      </geometry>
      <!-- <material name="LightGrey"/> -->
    </visual>
    <collision>
      <origin rpy="0 0 3.141592653589793" xyz="0 0 0"/>
      <geometry>
        <mesh filename="meshes/collision/shoulder.stl"/>
      </geometry>
    </collision>
    <inertial>
      <mass value="3.7"/>
      <origin rpy="0 0 0" xyz="0 0 0"/>
      <inertia ixx="0.010267495893" ixy="0.0" ixz="0.0" iyy="0.010267495893" iyz="0.0" izz="0.00666"/>
    </inertial>
  </link>
  <link name="upper_arm_link">
    <visual>
      <origin rpy="1.5707963267948966 0 -1.5707963267948966" xyz="0 0 0.138"/>
      <geometry>
        <mesh filename="meshes/visual/upperarm.dae"/>
      </geometry>
      <!-- <material name="LightGrey"/> -->
    </visual>
    <collision>
      <origin rpy="1.5707963267948966 0 -1.5707963267948966" xyz="0 0 0.138"/>
      <geometry>
        <mesh filename="meshes/collision/upperarm.stl"/>
      </geometry>
    </collision>
    <inertial>
      <mass value="8.393"/>
      <origin rpy="0 1.5707963267948966 0" xyz="-0.2125 0.0 0.138"/>
      <inertia ixx="0.1338857818623325" ixy="0.0" ixz="0.0" iyy="0.1338857818623325" iyz="0.0" izz="0.0151074"/>
    </inertial>
  </link>
  <link name="forearm_link">
    <visual>
      <origin rpy="1.5707963267948966 0 -1.5707963267948966" xyz="0 0 0.007"/>
      <geometry>
        <mesh filename="meshes/visual/forearm.dae"/>
      </geometry>
      <!-- <material name="LightGrey"/> -->
    </visual>
    <collision>
      <origin rpy="1.5707963267948966 0 -1.5707963267948966" xyz="0 0 0.007"/>
      <geometry>
        <mesh filename="meshes/collision/forearm.stl"/>
      </geometry>
    </collision>
    <inertial>
      <mass value="2.275"/>
      <origin rpy="0 1.5707963267948966 0" xyz="-0.1961 0.0 0.007"/>
      <inertia ixx="0.031209355099586295" ixy="0.0" ixz="0.0" iyy="0.031209355099586295" iyz="0.0" izz="0.004095"/>
    </inertial>
  </link>
  <link name="wrist_1_link">
    <visual>
      <!-- TODO: Move this to a parameter -->
      <origin rpy="1.5707963267948966 0 0" xyz="0 0 -0.127"/>
      <geometry>
        <mesh filename="meshes/visual/wrist1.dae"/>
      </geometry>
      <!-- <material name="LightGrey"/> -->
    </visual>
    <collision>
      <origin rpy="1.5707963267948966 0 0" xyz="0 0 -0.127"/>
      <geometry>
        <mesh filename="meshes/collision/wrist1.stl"/>
      </geometry>
    </collision>
    <inertial>
      <mass value="1.219"/>
      <origin rpy="0 0 0" xyz="0 0 0"/>
      <inertia ixx="0.0025598989760400002" ixy="0.0" ixz="0.0" iyy="0.0025598989760400002" iyz="0.0" izz="0.0021942"/>
    </inertial>
  </link>
  <link name="wrist_2_link">
    <visual>
      <origin rpy="0 0 0" xyz="0 0 -0.0997"/>
      <geometry>
        <mesh filename="meshes/visual/wrist2.dae"/>
      </geometry>
      <!-- <material name="LightGrey"/> -->
    </visual>
    <collision>
      <origin rpy="0 0 0" xyz="0 0 -0.0997"/>
      <geometry>
        <mesh filename="meshes/collision/wrist2.stl"/>
      </geometry>
    </collision>
    <inertial>
      <mass value="1.219"/>
      <origin rpy="0 0 0" xyz="0 0 0"/>
      <inertia ixx="0.0025598989760400002" ixy="0.0" ixz="0.0" iyy="0.0025598989760400002" iyz="0.0" izz="0.0021942"/>
    </inertial>
  </link>
  <link name="wrist_3_link">
    <visual>
      <origin rpy="1.5707963267948966 0 0" xyz="0 0 -0.0989"/>
      <geometry>
        <mesh filename="meshes/visual/wrist3.dae"/>
      </geometry>
      <!-- <material name="LightGrey"/> -->
    </visual>
    <collision>
      <origin rpy="1.5707963267948966 0 0" xyz="0 0 -0.0989"/>
      <geometry>
        <mesh filename="meshes/collision/wrist3.stl"/>
      </geometry>
    </collision>
    <inertial>
      <mass value="0.1879"/>
      <origin rpy="0 0 0" xyz="0.0 0.0 -0.0229"/>
      <inertia ixx="9.890410052167731e-05" ixy="0.0" ixz="0.0" iyy="9.890410052167731e-05" iyz="0.0" izz="0.0001321171875"/>
    </inertial>
  </link>


  <!-- joints: main serial chain -->
  <joint name="base_offset_joint" type="fixed">
    <parent link="base_link"/>
    <child link="base_offset_link"/>
    <origin rpy="0 0 0" xyz="0 0 0"/>
  </joint>
  <joint name="base_link-base_link_inertia" type="fixed">
    <parent link="base_offset_link"/>
    <child link="base_link_inertia"/>
    <!-- 'base_link' is REP-103 aligned (so X+ forward), while the internal
           frames of the robot/controller have X+ pointing backwards.
           Use the joint between 'base_link' and 'base_link_inertia' (a dummy
           link/frame) to introduce the necessary rotation over Z (of pi rad).
      -->
    <origin rpy="0 0 1.5707963267948966" xyz="0 0 0"/>
  </joint>
  <joint name="shoulder_pan_joint" type="revolute">
    <parent link="base_link_inertia"/>
    <child link="shoulder_link"/>
    <origin rpy="0 0 0" xyz="0 0 0.1625"/>
    <axis xyz="0 0 1"/>
    <limit effort="150.0" lower="0.7853981633974483" upper="2.356194490192345" velocity="3.141592653589793"/>
    <dynamics damping="0" friction="0"/>
  </joint>
  <joint name="shoulder_lift_joint" type="revolute">
    <parent link="shoulder_link"/>
    <child link="upper_arm_link"/>
    <origin rpy="1.570796327 0 0" xyz="0 0 0"/>
    <axis xyz="0 0 1"/>
    <limit effort="150.0" lower="-1.7671458676442586" upper="-0.5890486225480862" velocity="3.141592653589793"/>
    <dynamics damping="0" friction="0"/>
  </joint>
  <joint name="elbow_joint" type="revolute">
    <parent link="upper_arm_link"/>
    <child link="forearm_link"/>
    <origin rpy="0 0 0" xyz="-0.425 0 0"/>
    <axis xyz="0 0 1"/>
    <limit effort="150.0" lower="-0.19634954084936207" upper="2.945243112740431" velocity="3.141592653589793"/>
    <dynamics damping="0" friction="0"/>
  </joint>
  <joint name="wrist_1_joint" type="revolute">
    <parent link="forearm_link"/>
    <child link="wrist_1_link"/>
    <origin rpy="0 0 0" xyz="-0.3922 0 0.1333"/>
    <axis xyz="0 0 1"/>
    <limit effort="28.0" lower="-1.9634954084936207" upper="1.1780972450961724" velocity="3.141592653589793"/>
    <dynamics damping="0" friction="0"/>
  </joint>
  <joint name="wrist_2_joint" type="revolute">
    <parent link="wrist_1_link"/>
    <child link="wrist_2_link"/>
    <origin rpy="1.570796327 0 0" xyz="0 -0.0997 -2.044881182297852e-11"/>
    <axis xyz="0 0 1"/>
    <limit effort="28.0" lower="0.0" upper="3.141592653589793" velocity="3.141592653589793"/>
    <dynamics damping="0" friction="0"/>
  </joint>
  <joint name="wrist_3_joint" type="revolute">
    <parent link="wrist_2_link"/>
    <child link="wrist_3_link"/>
    <origin rpy="1.570796326589793 3.141592653589793 3.141592653589793" xyz="0 0.0996 -2.042830148012698e-11"/>
    <axis xyz="0 0 1"/>
    <limit effort="28.0" lower="-3.141592653589793" upper="3.141592653589793" velocity="3.141592653589793"/>
    <dynamics damping="0" friction="0"/>
  </joint>



  <material name="RAL_9005_Jet_Black">
    <color rgba="0.055 0.055 0.063 1.0" />
  </material>
  <material name="RAL_9003_Signal_White">
    <color rgba="0.941 0.941 0.941 1.0" />
  </material>

  <link name="connector">
    <visual>
      <origin xyz="0 0 0" rpy="0 0 0" />
      <geometry>
        <mesh
          filename="meshes/connector.stl"  scale="0.001 0.001 0.001"/>
      </geometry>
      <material name="RAL_9005_Jet_Black"/>
    </visual>
  </link>
  <joint name="connector_joint" type="fixed">
    <parent link="wrist_3_link"/>
    <child link="connector"/>
    <origin rpy="3.141592 1.57079 0" xyz="0 0 0.0305"/>
  </joint>


  <joint name="arm_hand_joint" type="fixed">
    <origin xyz="0.03 0.01 0.123" rpy="0. -1.57079 -1.57079"/>
    <parent link="wrist_3_link"/>
    <child link="base"/>
  </joint>
  
  
  <link name="base"/>
  <joint name="base_joint" type="fixed">
    <parent link="base"/>
    <child link="right_hand_link"/>
    <origin rpy="-1.57079 0 1.57079" xyz="-0.1 -0.03 -0.01"/>
  </joint>

  
  <link
    name="right_hand_link">
    <inertial>
      <origin
        xyz="-0.00366836214548078 0.0100351220466308 -0.0582695185384578"
        rpy="0 0 0" />
      <mass
        value="0.53903004" />
      <inertia
        ixx="0.00046462"
        ixy="0.00000004"
        ixz="-0.00005128"
        iyy="0.00064214"
        iyz="0.00000217"
        izz="0.00027541" />
    </inertial>
    <visual>
      <origin
        xyz="0 0 0"
        rpy="0 0 0" />
      <geometry>
        <mesh
          filename="meshes/right_hand_link.STL" />
      </geometry>
      <material name="RAL_9005_Jet_Black"/>
    </visual>
    <collision>
      <origin
        xyz="0 0 0"
        rpy="0 0 0" />
      <geometry>
        <mesh
          filename="meshes/right_hand_link.STL" />
      </geometry>
    </collision>
  </link>
  <link
    name="right_hand_ee_link">
    <visual>
      <origin
        xyz="0 0 0"
        rpy="0 0 0" />
      <geometry>
        <mesh
          filename="meshes/right_hand_ee_link.STL" />
      </geometry>
      <material name="RAL_9005_Jet_Black"/>
    </visual>
  </link>
  <joint
    name="right_hand_ee_joint"
    type="fixed">
    <origin
      xyz="0 0 -0.065"
      rpy="0 0 0" />
    <parent
      link="right_hand_link" />
    <child
      link="right_hand_ee_link" />
    <axis
      xyz="0 0 0" />
    <dynamics
      damping="0"
      friction="0" />
  </joint>
  <link
    name="right_hand_back_link">
    <visual>
      <origin
        xyz="0 0 0"
        rpy="0 0 0" />
      <geometry>
        <mesh
          filename="meshes/right_hand_back_link.STL" />
      </geometry>
      <material name="RAL_9003_Signal_White"/>
    </visual>
  </link>
  <joint
    name="right_hand_back_joint"
    type="fixed">
    <origin
      xyz="0 0 -0.065"
      rpy="0 0 0" />
    <parent
      link="right_hand_link" />
    <child
      link="right_hand_back_link" />
    <axis
      xyz="0 0 0" />
    <dynamics
      damping="0"
      friction="0" />
  </joint>
  <link
    name="right_hand_thumb_bend_link">
    <inertial>
      <origin
        xyz="0.0144358799903648 -0.00116534489100676 -5.40665183231849E-05"
        rpy="0 0 0" />
      <mass
        value="0.01174632" />
      <inertia
        ixx="0.00000062"
        ixy="-0.00000004"
        ixz="-0.00000007"
        iyy="0.0000016"
        iyz="0.00000000001"
        izz="0.00000162" />
    </inertial>
    <visual>
      <origin
        xyz="0 0 0"
        rpy="0 0 0" />
      <geometry>
        <mesh
          filename="meshes/right_hand_thumb_bend_link.STL" />
      </geometry>
      <material name="RAL_9005_Jet_Black"/>
    </visual>
    <collision>
      <origin
        xyz="0 0 0"
        rpy="0 0 0" />
      <geometry>
        <mesh
          filename="meshes/right_hand_thumb_bend_link.STL" />
      </geometry>
    </collision>
  </link>
  <joint
    name="right_hand_thumb_bend_joint"
    type="revolute">
    <origin
      xyz="0.0228 0.0095 -0.0305"
      rpy="0 0 0" />
    <parent
      link="right_hand_link" />
    <child
      link="right_hand_thumb_bend_link" />
    <axis
      xyz="0 0 1" />
    <limit
      lower="0"
      upper="1.832"
      effort="1.1"
      velocity="8.63" />
    <dynamics
      damping="1.0"
      friction="0.8" />
       <joint_properties friction="0.8"/>
  </joint>
  <link
    name="right_hand_thumb_rota_link1">
    <inertial>
      <origin
        xyz="0.0287681482733488 -0.00036176529547633 -0.00133929681686046"
        rpy="0 0 0" />
      <mass
        value="0.13266642" />
      <inertia
        ixx="0.00001699"
        ixy="-0.00000791"
        ixz="-0.00000182"
        iyy="0.00003679"
        iyz="-0.00000196"
        izz="0.00004374" />
    </inertial>
    <visual>
      <origin
        xyz="0 0 0"
        rpy="0 0 0" />
      <geometry>
        <mesh
          filename="meshes/right_hand_thumb_rota_link1.STL" />
      </geometry>
      <material name="RAL_9005_Jet_Black"/>
    </visual>
    <collision>
      <origin
        xyz="0 0 0"
        rpy="0 0 0" />
      <geometry>
        <mesh
          filename="meshes/right_hand_thumb_rota_link1.STL" />
      </geometry>
    </collision>
  </link>
  <joint
    name="right_hand_thumb_rota_joint1"
    type="revolute">
    <origin
      xyz="0.028599 0.0083177 0.00178"
      rpy="0.2618 0 0.0407" />
    <parent
      link="right_hand_thumb_bend_link" />
    <child
      link="right_hand_thumb_rota_link1" />
    <axis
      xyz="0 1 0" />
    <limit
      lower="-0.698"
      upper="1.745"
      effort="1.1"
      velocity="8.63" />
    <dynamics
      damping="1.0"
      friction="0.8" />
       <joint_properties friction="0.8"/>
  </joint>
  <link
    name="right_hand_thumb_rotaback_link1">
    <visual>
      <origin
        xyz="0 0 0"
        rpy="0 0 0" />
      <geometry>
        <mesh
          filename="meshes/right_hand_thumb_rotaback_link1.STL" />
      </geometry>
      <material name="RAL_9003_Signal_White"/>
    </visual>
  </link>
  <joint
    name="right_hand_thumb_rotaback_joint1"
    type="fixed">
    <origin
      xyz="0.0553000000000007 0 0"
      rpy="0 0 0" />
    <parent
      link="right_hand_thumb_rota_link1" />
    <child
      link="right_hand_thumb_rotaback_link1" />
    <axis
      xyz="0 0 0" />
    <dynamics
      damping="0"
      friction="0" />
  </joint>
  <link
    name="right_hand_thumb_rota_link2">
    <inertial>
      <origin
        xyz="0.0225340009927979 -0.000881600697645881 -0.000614548321208525"
        rpy="0 0 0" />
      <mass
        value="0.04336091" />
      <inertia
        ixx="0.00000388"
        ixy="0.00000000001"
        ixz="0.00000015"
        iyy="0.00000902"
        iyz="-0.00000042"
        izz="0.00001046" />
    </inertial>
    <visual>
      <origin
        xyz="0 0 0"
        rpy="0 0 0" />
      <geometry>
        <mesh
          filename="meshes/right_hand_thumb_rota_link2.STL" />
      </geometry>
      <material name="RAL_9005_Jet_Black"/>
    </visual>
    <collision>
      <origin
        xyz="0 0 0"
        rpy="0 0 0" />
      <geometry>
        <mesh
          filename="meshes/right_hand_thumb_rota_link2.STL" />
      </geometry>
    </collision>
  </link>
  <joint
    name="right_hand_thumb_rota_joint2"
    type="revolute">
    <origin
      xyz="0.0553 0 0"
      rpy="0 0 0" />
    <parent
      link="right_hand_thumb_rota_link1" />
    <child
      link="right_hand_thumb_rota_link2" />
    <axis
      xyz="0 1 0" />
    <limit
      lower="0"
      upper="1.745"
      effort="0.4"
      velocity="14.38" />
    <dynamics
      damping="1.0"
      friction="0.8" />
       <joint_properties friction="0.8"/>
  </joint>
  <link
    name="right_hand_thumb_rotaback_link2">
    <visual>
      <origin
        xyz="0 0 0"
        rpy="0 0 0" />
      <geometry>
        <mesh
          filename="meshes/right_hand_thumb_rotaback_link2.STL" />
      </geometry>
      <material name="RAL_9003_Signal_White"/>
    </visual>
  </link>
  <joint
    name="right_hand_thumb_rotaback_joint2"
    type="fixed">
    <origin
      xyz="0.0502276499414862 0 0"
      rpy="0 0 0" />
    <parent
      link="right_hand_thumb_rota_link2" />
    <child
      link="right_hand_thumb_rotaback_link2" />
    <axis
      xyz="0 0 0" />
    <dynamics
      damping="0"
      friction="0" />
  </joint>
  <link
    name="right_hand_thumb_rota_tip">
    <visual>
      <origin
        xyz="0 0 0"
        rpy="0 0 0" />
      <geometry>
        <mesh
          filename="meshes/right_hand_thumb_rota_tip.STL" />
      </geometry>
      <material name="RAL_9005_Jet_Black"/>
    </visual>
  </link>
  <joint
    name="right_hand_thumb_rota_joint3"
    type="fixed">
    <origin
      xyz="0.0502276499414862 0 0"
      rpy="0 0 0" />
    <parent
      link="right_hand_thumb_rota_link2" />
    <child
      link="right_hand_thumb_rota_tip" />
    <axis
      xyz="0 0 0" />
    <dynamics
      damping="0"
      friction="0" />
  </joint>
  <link
    name="right_hand_index_bend_link">
    <inertial>
      <origin
        xyz="0.000118997558760787 -0.000715851164577269 -0.0111903014853532"
        rpy="0 0 0" />
      <mass
        value="0.06910833" />
      <inertia
        ixx="0.0000174"
        ixy="0.00000001"
        ixz="0.00000014"
        iyy="0.00001677"
        iyz="-0.00000012"
        izz="0.00000345" />
    </inertial>
    <visual>
      <origin
        xyz="0 0 0"
        rpy="0 0 0" />
      <geometry>
        <mesh
          filename="meshes/right_hand_index_bend_link.STL" />
      </geometry>
      <material name="RAL_9005_Jet_Black"/>
    </visual>
    <collision>
      <origin
        xyz="0 0 0"
        rpy="0 0 0" />
      <geometry>
        <mesh
          filename="meshes/right_hand_index_bend_link.STL" />
      </geometry>
    </collision>
  </link>
  <joint
    name="right_hand_index_bend_joint"
    type="revolute">
    <origin
      xyz="0.0265 0.0065 -0.0899"
      rpy="0 0 0" />
    <parent
      link="right_hand_link" />
    <child
      link="right_hand_index_bend_link" />
    <axis
      xyz="0 -1 0" />
    <limit
      lower="-0.174"
      upper="0.174"
      effort="0.4"
      velocity="14.38" />
    <dynamics
      damping="1.0"
      friction="0.8" />
       <joint_properties friction="0.8"/>
  </joint>
  <link
    name="right_hand_index_rota_link1">
    <inertial>
      <origin
        xyz="0.000133008106573459 0.000632930512954057 -0.0355868719939061"
        rpy="0 0 0" />
      <mass
        value="0.06298297" />
      <inertia
        ixx="0.00001738"
        ixy="0.00000000001"
        ixz="0.00000028"
        iyy="0.00001686"
        iyz="0.00000019"
        izz="0.0000032" />
    </inertial>
    <visual>
      <origin
        xyz="0 0 0"
        rpy="0 0 0" />
      <geometry>
        <mesh
          filename="meshes/right_hand_index_rota_link1.STL" />
      </geometry>
      <material name="RAL_9005_Jet_Black"/>
    </visual>
    <collision>
      <origin
        xyz="0 0 0"
        rpy="0 0 0" />
      <geometry>
        <mesh
          filename="meshes/right_hand_index_rota_link1.STL" />
      </geometry>
    </collision>
  </link>
  <joint
    name="right_hand_index_joint1"
    type="revolute">
    <origin
      xyz="0 0 -0.0178"
      rpy="0 0 0" />
    <parent
      link="right_hand_index_bend_link" />
    <child
      link="right_hand_index_rota_link1" />
    <axis
      xyz="1 0 0" />
    <limit
      lower="0"
      upper="1.919"
      effort="1.1"
      velocity="8.63" />
    <dynamics
      damping="1.0"
      friction="0.8" />
       <joint_properties friction="0.8"/>
  </joint>
  <link
    name="right_hand_index_rotaback_link1">
    <visual>
      <origin
        xyz="0 0 0"
        rpy="0 0 0" />
      <geometry>
        <mesh
          filename="meshes/right_hand_index_rotaback_link1.STL" />
      </geometry>
      <material name="RAL_9003_Signal_White"/>
    </visual>
  </link>
  <joint
    name="right_hand_index_rotaback_joint1"
    type="fixed">
    <origin
      xyz="0 0 -0.0557999999999955"
      rpy="0 0 0" />
    <parent
      link="right_hand_index_rota_link1" />
    <child
      link="right_hand_index_rotaback_link1" />
    <axis
      xyz="0 0 0" />
    <dynamics
      damping="0"
      friction="0" />
  </joint>
  <link
    name="right_hand_index_rota_link2">
    <inertial>
      <origin
        xyz="-0.000248361661985549 0.00119905190206764 -0.0213789854478675"
        rpy="0 0 0" />
      <mass
        value="0.01588724" />
      <inertia
        ixx="0.00000277"
        ixy="0.00000000001"
        ixz="0.00000012"
        iyy="0.00000283"
        iyz="0.00000007"
        izz="0.00000085" />
    </inertial>
    <visual>
      <origin
        xyz="0 0 0"
        rpy="0 0 0" />
      <geometry>
        <mesh
          filename="meshes/right_hand_index_rota_link2.STL" />
      </geometry>
      <material name="RAL_9005_Jet_Black"/>
    </visual>
    <collision>
      <origin
        xyz="0 0 0"
        rpy="0 0 0" />
      <geometry>
        <mesh
          filename="meshes/right_hand_index_rota_link2.STL" />
      </geometry>
    </collision>
  </link>
  <joint
    name="right_hand_index_joint2"
    type="revolute">
    <origin
      xyz="0 0 -0.0558"
      rpy="0 0 0" />
    <parent
      link="right_hand_index_rota_link1" />
    <child
      link="right_hand_index_rota_link2" />
    <axis
      xyz="1 0 0" />
    <limit
      lower="0"
      upper="1.919"
      effort="0.4"
      velocity="14.38" />
    <dynamics
      damping="1.0"
      friction="0.8" />
       <joint_properties friction="0.8"/>
  </joint>
  <link
    name="right_hand_index_rotaback_link2">
    <visual>
      <origin
        xyz="0 0 0"
        rpy="0 0 0" />
      <geometry>
        <mesh
          filename="meshes/right_hand_index_rotaback_link2.STL" />
      </geometry>
      <material name="RAL_9003_Signal_White"/>
    </visual>
  </link>
  <joint
    name="right_hand_index_rotaback_joint2"
    type="fixed">
    <origin
      xyz="0 0 -0.0422482924089416"
      rpy="0 0 0" />
    <parent
      link="right_hand_index_rota_link2" />
    <child
      link="right_hand_index_rotaback_link2" />
    <axis
      xyz="0 0 0" />
    <dynamics
      damping="0"
      friction="0" />
  </joint>
  <link
    name="right_hand_index_rota_tip">
    <visual>
      <origin
        xyz="0 0 0"
        rpy="0 0 0" />
      <geometry>
        <mesh
          filename="meshes/right_hand_index_rota_tip.STL" />
      </geometry>
      <material name="RAL_9005_Jet_Black"/>
    </visual>
  </link>
  <joint
    name="right_hand_index_rota_joint3"
    type="fixed">
    <origin
      xyz="0 0 -0.0422482924089416"
      rpy="0 0 0" />
    <parent
      link="right_hand_index_rota_link2" />
    <child
      link="right_hand_index_rota_tip" />
    <axis
      xyz="0 0 0" />
    <dynamics
      damping="0"
      friction="0" />
  </joint>
  <link
    name="right_hand_mid_link1">
    <inertial>
      <origin
        xyz="3.58049083993136E-05 0.000530417592106078 -0.0332784671157236"
        rpy="0 0 0" />
      <mass
        value="0.06298297" />
      <inertia
        ixx="0.00001738"
        ixy="0.00000000001"
        ixz="0.00000028"
        iyy="0.00001686"
        iyz="0.00000019"
        izz="0.0000032" />
    </inertial>
    <visual>
      <origin
        xyz="0 0 0"
        rpy="0 0 0" />
      <geometry>
        <mesh
          filename="meshes/right_hand_mid_link1.STL" />
      </geometry>
      <material name="RAL_9005_Jet_Black"/>
    </visual>
    <collision>
      <origin
        xyz="0 0 0"
        rpy="0 0 0" />
      <geometry>
        <mesh
          filename="meshes/right_hand_mid_link1.STL" />
      </geometry>
    </collision>
  </link>
  <joint
    name="right_hand_mid_joint1"
    type="revolute">
    <origin
      xyz="0.004 0.0065 -0.1082"
      rpy="0 0 0" />
    <parent
      link="right_hand_link" />
    <child
      link="right_hand_mid_link1" />
    <axis
      xyz="1 0 0" />
    <limit
      lower="0"
      upper="1.919"
      effort="1.1"
      velocity="8.63" />
    <dynamics
      damping="1.0"
      friction="0.8" />
       <joint_properties friction="0.8"/>
  </joint>
  <link
    name="right_hand_midback_link1">
    <visual>
      <origin
        xyz="0 0 0"
        rpy="0 0 0" />
      <geometry>
        <mesh
          filename="meshes/right_hand_midback_link1.STL" />
      </geometry>
      <material name="RAL_9003_Signal_White"/>
    </visual>
  </link>
  <joint
    name="right_hand_midback_joint1"
    type="fixed">
    <origin
      xyz="0 0 -0.0558"
      rpy="0 0 0" />
    <parent
      link="right_hand_mid_link1" />
    <child
      link="right_hand_midback_link1" />
    <axis
      xyz="0 0 0" />
    <dynamics
      damping="0"
      friction="0" />
  </joint>
  <link
    name="right_hand_mid_link2">
    <inertial>
      <origin
        xyz="-0.000248364601983051 0.00119905076177324 -0.0213789908421273"
        rpy="0 0 0" />
      <mass
        value="0.01624108" />
      <inertia
        ixx="0.00000281"
        ixy="0.00000000001"
        ixz="0.00000012"
        iyy="0.00000287"
        iyz="0.00000007"
        izz="0.00000086" />
    </inertial>
    <visual>
      <origin
        xyz="0 0 0"
        rpy="0 0 0" />
      <geometry>
        <mesh
          filename="meshes/right_hand_mid_link2.STL" />
      </geometry>
      <material name="RAL_9005_Jet_Black"/>
    </visual>
    <collision>
      <origin
        xyz="0 0 0"
        rpy="0 0 0" />
      <geometry>
        <mesh
          filename="meshes/right_hand_mid_link2.STL" />
      </geometry>
    </collision>
  </link>
  <joint
    name="right_hand_mid_joint2"
    type="revolute">
    <origin
      xyz="0 0 -0.0558"
      rpy="0 0 0" />
    <parent
      link="right_hand_mid_link1" />
    <child
      link="right_hand_mid_link2" />
    <axis
      xyz="1 0 0" />
    <limit
      lower="0"
      upper="1.919"
      effort="0.4"
      velocity="14.38" />
    <dynamics
      damping="1.0"
      friction="0.8" />
       <joint_properties friction="0.8"/>
  </joint>
  <link
    name="right_hand_midback_link2">
    <visual>
      <origin
        xyz="0 0 0"
        rpy="0 0 0" />
      <geometry>
        <mesh
          filename="meshes/right_hand_midback_link2.STL" />
      </geometry>
      <material name="RAL_9003_Signal_White"/>
    </visual>
  </link>
  <joint
    name="right_hand_midback_joint2"
    type="fixed">
    <origin
      xyz="0 0 -0.042248"
      rpy="0 0 0" />
    <parent
      link="right_hand_mid_link2" />
    <child
      link="right_hand_midback_link2" />
    <axis
      xyz="0 0 0" />
    <dynamics
      damping="0"
      friction="0" />
  </joint>
  <link
    name="right_hand_mid_tip">
    <visual>
      <origin
        xyz="0 0 0"
        rpy="0 0 0" />
      <geometry>
        <mesh
          filename="meshes/right_hand_mid_tip.STL" />
      </geometry>
      <material name="RAL_9005_Jet_Black"/>
    </visual>
  </link>
  <joint
    name="right_hand_mid_joint3"
    type="fixed">
    <origin
      xyz="0 0 -0.0422482924089417"
      rpy="0 0 0" />
    <parent
      link="right_hand_mid_link2" />
    <child
      link="right_hand_mid_tip" />
    <axis
      xyz="0 0 0" />
    <dynamics
      damping="0"
      friction="0" />
  </joint>
  <link
    name="right_hand_ring_link1">
    <inertial>
      <origin
        xyz="3.58049083615322E-05 0.000530417592105594 -0.0332784671157224"
        rpy="0 0 0" />
      <mass
        value="0.06298297" />
      <inertia
        ixx="0.00001738"
        ixy="0.00000000001"
        ixz="0.00000028"
        iyy="0.00001686"
        iyz="0.00000019"
        izz="0.0000032" />
    </inertial>
    <visual>
      <origin
        xyz="0 0 0"
        rpy="0 0 0" />
      <geometry>
        <mesh
          filename="meshes/right_hand_ring_link1.STL" />
      </geometry>
      <material name="RAL_9005_Jet_Black"/>
    </visual>
    <collision>
      <origin
        xyz="0 0 0"
        rpy="0 0 0" />
      <geometry>
        <mesh
          filename="meshes/right_hand_ring_link1.STL" />
      </geometry>
    </collision>
  </link>
  <joint
    name="right_hand_ring_joint1"
    type="revolute">
    <origin
      xyz="-0.016 0.0065 -0.1052"
      rpy="0 0 0" />
    <parent
      link="right_hand_link" />
    <child
      link="right_hand_ring_link1" />
    <axis
      xyz="1 0 0" />
    <limit
      lower="0"
      upper="1.919"
      effort="1.1"
      velocity="8.63" />
    <dynamics
      damping="1.0"
      friction="0.8" />
       <joint_properties friction="0.8"/>
  </joint>
  <link
    name="right_hand_ringback_link1">
    <visual>
      <origin
        xyz="0 0 0"
        rpy="0 0 0" />
      <geometry>
        <mesh
          filename="meshes/right_hand_ringback_link1.STL" />
      </geometry>
      <material name="RAL_9003_Signal_White"/>
    </visual>
  </link>
  <joint
    name="right_hand_ringback_joint1"
    type="fixed">
    <origin
      xyz="0 0 -0.0558000000000002"
      rpy="0 0 0" />
    <parent
      link="right_hand_ring_link1" />
    <child
      link="right_hand_ringback_link1" />
    <axis
      xyz="0 0 0" />
    <dynamics
      damping="0"
      friction="0" />
  </joint>
  <link
    name="right_hand_ring_link2">
    <inertial>
      <origin
        xyz="-0.000248364602035429 0.00119905076177346 -0.0213789908421257"
        rpy="0 0 0" />
      <mass
        value="0.01624108" />
      <inertia
        ixx="0.00000281"
        ixy="0.00000000001"
        ixz="0.00000012"
        iyy="0.00000287"
        iyz="0.00000007"
        izz="0.00000086" />
    </inertial>
    <visual>
      <origin
        xyz="0 0 0"
        rpy="0 0 0" />
      <geometry>
        <mesh
          filename="meshes/right_hand_ring_link2.STL" />
      </geometry>
      <material name="RAL_9005_Jet_Black"/>
    </visual>
    <collision>
      <origin
        xyz="0 0 0"
        rpy="0 0 0" />
      <geometry>
        <mesh
          filename="meshes/right_hand_ring_link2.STL" />
      </geometry>
    </collision>
  </link>
  <joint
    name="right_hand_ring_joint2"
    type="revolute">
    <origin
      xyz="0 0 -0.0558"
      rpy="0 0 0" />
    <parent
      link="right_hand_ring_link1" />
    <child
      link="right_hand_ring_link2" />
    <axis
      xyz="1 0 0" />
    <limit
      lower="0"
      upper="1.919"
      effort="0.4"
      velocity="14.38" />
    <dynamics
      damping="1.0"
      friction="0.8" />
       <joint_properties friction="0.8"/>
  </joint>
  <link
    name="right_hand_ringback_link2">
    <visual>
      <origin
        xyz="0 0 0"
        rpy="0 0 0" />
      <geometry>
        <mesh
          filename="meshes/right_hand_ringback_link2.STL" />
      </geometry>
      <material name="RAL_9003_Signal_White"/>
    </visual>
  </link>
  <joint
    name="right_hand_ringback_joint2"
    type="fixed">
    <origin
      xyz="0 0 -0.0422482924089403"
      rpy="0 0 0" />
    <parent
      link="right_hand_ring_link2" />
    <child
      link="right_hand_ringback_link2" />
    <axis
      xyz="0 0 0" />
    <dynamics
      damping="0"
      friction="0" />
  </joint>
  <link
    name="right_hand_ring_tip">
    <visual>
      <origin
        xyz="0 0 0"
        rpy="0 0 0" />
      <geometry>
        <mesh
          filename="meshes/right_hand_ring_tip.STL" />
      </geometry>
      <material name="RAL_9005_Jet_Black"/>
    </visual>
  </link>
  <joint
    name="right_hand_ring_joint3"
    type="fixed">
    <origin
      xyz="0 0 -0.0422482924089403"
      rpy="0 0 0" />
    <parent
      link="right_hand_ring_link2" />
    <child
      link="right_hand_ring_tip" />
    <axis
      xyz="0 0 0" />
    <dynamics
      damping="0"
      friction="0" />
  </joint>
  <link
    name="right_hand_pinky_link1">
    <inertial>
      <origin
        xyz="3.58049083611298E-05 0.000530417592105422 -0.0332784671157224"
        rpy="0 0 0" />
      <mass
        value="0.06298297" />
      <inertia
        ixx="0.00001738"
        ixy="0.00000000001"
        ixz="0.00000028"
        iyy="0.00001686"
        iyz="0.00000019"
        izz="0.0000032" />
    </inertial>
    <visual>
      <origin
        xyz="0 0 0"
        rpy="0 0 0" />
      <geometry>
        <mesh
          filename="meshes/right_hand_pinky_link1.STL" />
      </geometry>
      <material name="RAL_9005_Jet_Black"/>
    </visual>
    <collision>
      <origin
        xyz="0 0 0"
        rpy="0 0 0" />
      <geometry>
        <mesh
          filename="meshes/right_hand_pinky_link1.STL" />
      </geometry>
    </collision>
  </link>
  <joint
    name="right_hand_pinky_joint1"
    type="revolute">
    <origin
      xyz="-0.036 0.0065 -0.1022"
      rpy="0 0 0" />
    <parent
      link="right_hand_link" />
    <child
      link="right_hand_pinky_link1" />
    <axis
      xyz="1 0 0" />
    <limit
      lower="0"
      upper="1.919"
      effort="1.1"
      velocity="8.63" />
    <dynamics
      damping="1.0"
      friction="0.8" />
       <joint_properties friction="0.8"/>
  </joint>
  <link
    name="right_hand_pinkyback_link1">
    <visual>
      <origin
        xyz="0 0 0"
        rpy="0 0 0" />
      <geometry>
        <mesh
          filename="meshes/right_hand_pinkyback_link1.STL" />
      </geometry>
      <material name="RAL_9003_Signal_White"/>
    </visual>
  </link>
  <joint
    name="right_hand_pinkyback_joint1"
    type="fixed">
    <origin
      xyz="0 0 -0.0558000000000001"
      rpy="0 0 0" />
    <parent
      link="right_hand_pinky_link1" />
    <child
      link="right_hand_pinkyback_link1" />
    <axis
      xyz="0 0 0" />
    <dynamics
      damping="0"
      friction="0" />
  </joint>
  <link
    name="right_hand_pinky_link2">
    <inertial>
      <origin
        xyz="-0.000248361662015334 0.0011990519020671 -0.0213789854478658"
        rpy="0 0 0" />
      <mass
        value="0.01624108" />
      <inertia
        ixx="0.00000281"
        ixy="0.00000000001"
        ixz="0.00000012"
        iyy="0.00000287"
        iyz="0.00000007"
        izz="0.00000086" />
    </inertial>
    <visual>
      <origin
        xyz="0 0 0"
        rpy="0 0 0" />
      <geometry>
        <mesh
          filename="meshes/right_hand_pinky_link2.STL" />
      </geometry>
      <material name="RAL_9005_Jet_Black"/>
    </visual>
    <collision>
      <origin
        xyz="0 0 0"
        rpy="0 0 0" />
      <geometry>
        <mesh
          filename="meshes/right_hand_pinky_link2.STL" />
      </geometry>
    </collision>
  </link>
  <joint
    name="right_hand_pinky_joint2"
    type="revolute">
    <origin
      xyz="0 0 -0.0558"
      rpy="0 0 0" />
    <parent
      link="right_hand_pinky_link1" />
    <child
      link="right_hand_pinky_link2" />
    <axis
      xyz="1 0 0" />
    <limit
      lower="0"
      upper="1.919"
      effort="1.4"
      velocity="14.38" />
    <dynamics
      damping="1.0"
      friction="0.8" />
       <joint_properties friction="0.8"/>
  </joint>
  <link
    name="right_hand_pinkyback_link2">
    <visual>
      <origin
        xyz="0 0 0"
        rpy="0 0 0" />
      <geometry>
        <mesh
          filename="meshes/right_hand_pinkyback_link2.STL" />
      </geometry>
      <material name="RAL_9003_Signal_White"/>
    </visual>
  </link>
  <joint
    name="right_hand_pinkyback_joint2"
    type="fixed">
    <origin
      xyz="0 0 -0.0422482924089404"
      rpy="0 0 0" />
    <parent
      link="right_hand_pinky_link2" />
    <child
      link="right_hand_pinkyback_link2" />
    <axis
      xyz="0 0 0" />
    <dynamics
      damping="0"
      friction="0" />
  </joint>
  <link
    name="right_hand_pinky_tip">
    <visual>
      <origin
        xyz="0 0 0"
        rpy="0 0 0" />
      <geometry>
        <mesh
          filename="meshes/right_hand_pinky_tip.STL" />
      </geometry>
      <material name="RAL_9005_Jet_Black"/>
    </visual>
  </link>
  <joint
    name="right_hand_pinky_joint3"
    type="fixed">
    <origin
      xyz="0 0 -0.0422482924089404"
      rpy="0 0 0" />
    <parent
      link="right_hand_pinky_link2" />
    <child
      link="right_hand_pinky_tip" />
    <axis
      xyz="0 0 0" />
    <dynamics
      damping="0"
      friction="0" />
  </joint>
</robot>
